#Exception inside except block

try:
    raise(1)
except(e):
    raise(e)
end
